#VRML_SIM R2025a utf8

EXTERNPROTO "https://raw.githubusercontent.com/cyberbotics/webots/R2025a/projects/objects/backgrounds/protos/TexturedBackground.proto"
EXTERNPROTO "https://raw.githubusercontent.com/cyberbotics/webots/R2025a/projects/objects/backgrounds/protos/TexturedBackgroundLight.proto"
EXTERNPROTO "https://raw.githubusercontent.com/cyberbotics/webots/R2025a/projects/objects/floors/protos/RectangleArena.proto"

WorldInfo {
  basicTimeStep 1
  coordinateSystem "NUE"
}
Viewpoint {
  orientation 0.32722355449769547 0.5261191402369217 0.7849352811909119 4.162690324512787
  position -0.7585889604536374 2.410794855091863 -4.983838901120547
}
TexturedBackground {
}
TexturedBackgroundLight {
}
Robot {
  translation -2.426287606522904 0.24075542655643106 -0.8805004057129228
  rotation 0.22035255261710046 -0.9496047621640668 -0.2229249834147222 0.3350009228204678
  children [
    Shape {
      appearance PBRAppearance {
        baseColor 0 0.9 0.9
        roughness 1
        metalness 0
      }
      geometry Box {
        size 0.4 0.08 0.2
      }
    }
    HingeJoint {
      jointParameters HingeJointParameters {
        position -7.6357343178786e-06
        anchor 0.15 -0.02 0.12
        minStop -0.8
        maxStop 0.8
        dampingConstant 0.05
      }
      device [
        RotationalMotor {
          name "FL_hip_yaw"
          maxVelocity 5
          maxTorque 5
        }
        PositionSensor {
          name "FL_hip_yaw_sensor"
        }
      ]
      endPoint Solid {
        translation 0.1499999701008902 -0.020033508392467887 0.11986262938814393
        rotation -1 0 0 0.13090732963388924
        children [
          Shape {
            appearance PBRAppearance {
              baseColor 1 0.2 0
              roughness 1
              metalness 0
            }
            geometry Sphere {
              radius 0.025
            }
          }
          Pose {
            translation 0 0 0.035
            children [
              Shape {
                appearance PBRAppearance {
                  baseColor 0.7 0.2 0.8
                  roughness 1
                  metalness 0
                }
                geometry Box {
                  size 0.035 0.035 0.07
                }
              }
            ]
          }
          HingeJoint {
            jointParameters HingeJointParameters {
              position 0.9246738902192374
              axis 0 0 1
              anchor 0 0 0.07
              minStop -1.57
              maxStop 1.57
              dampingConstant 0.05
            }
            device [
              RotationalMotor {
                name "FL_hip_pitch"
                maxVelocity 5
                maxTorque 5
              }
              PositionSensor {
                name "FL_hip_pitch_sensor"
              }
            ]
            endPoint Solid {
              translation 0 0 0.07
              rotation 0 0 0.9999999999999999 0.9246738902192374
              children [
                Shape {
                  appearance PBRAppearance {
                    baseColor 0.1 0.2 1
                    roughness 1
                    metalness 0
                  }
                  geometry Sphere {
                    radius 0.022
                  }
                }
                Pose {
                  translation 0 -0.08 0
                  children [
                    Shape {
                      appearance PBRAppearance {
                        baseColor 0.6 0.1 0.6
                        roughness 1
                        metalness 0
                      }
                      geometry Box {
                        size 0.035 0.16 0.035
                      }
                    }
                  ]
                }
                HingeJoint {
                  jointParameters HingeJointParameters {
                    position -1.851070253455685
                    axis 0 0 1
                    anchor 0 -0.16 0
                    minStop -2.2
                    maxStop 0.2
                    dampingConstant 0.05
                  }
                  device [
                    RotationalMotor {
                      name "FL_knee_pitch"
                      maxVelocity 5
                      maxTorque 5
                    }
                    PositionSensor {
                      name "FL_knee_pitch_sensor"
                    }
                  ]
                  endPoint Solid {
                    translation 0 -0.16 0
                    rotation 0 0 -1 1.851070253455685
                    children [
                      Shape {
                        appearance PBRAppearance {
                          baseColor 0.1 0.2 1
                          roughness 1
                          metalness 0
                        }
                        geometry Sphere {
                          radius 0.02
                        }
                      }
                      Pose {
                        translation 0 -0.08 0
                        children [
                          Shape {
                            appearance PBRAppearance {
                              baseColor 0.8 0.7 0.2
                              roughness 1
                              metalness 0
                            }
                            geometry Box {
                              size 0.03 0.16 0.03
                            }
                          }
                        ]
                      }
                      Pose {
                        translation 0 -0.16 0
                        children [
                          Shape {
                            appearance PBRAppearance {
                              baseColor 0 0 0
                              roughness 1
                              metalness 0
                            }
                            geometry Sphere {
                              radius 0.018
                            }
                          }
                        ]
                      }
                    ]
                    name "FL_L3_shank_link"
                    boundingObject Pose {
                      translation 0 -0.08 0
                      children [
                        Box {
                          size 0.03 0.16 0.03
                        }
                      ]
                    }
                    physics Physics {
                      density -1
                      mass 0.08
                      centerOfMass [
                        0 -0.08 0
                      ]
                    }
                    linearVelocity -0.3045142510610042 -0.2471075982151732 -0.09042763177853083
                    angularVelocity -0.1896865351842305 0.28991001263957916 -0.3129614303512773
                  }
                }
              ]
              name "FL_L2_thigh_link"
              boundingObject Pose {
                translation 0 -0.08 0
                children [
                  Box {
                    size 0.035 0.16 0.035
                  }
                ]
              }
              physics Physics {
                density -1
                mass 0.12
                centerOfMass [
                  0 -0.08 0
                ]
              }
              linearVelocity -0.16247565745815973 -0.12150183498546382 -0.08455462541911547
              angularVelocity 0.4740690706664644 0.1382820424895198 -2.384074945741335
            }
          }
        ]
        name "FL_L1_yaw_link"
        boundingObject Pose {
          translation 0 0 0.035
          children [
            Box {
              size 0.035 0.035 0.07
            }
          ]
        }
        physics Physics {
          density -1
          mass 0.05
          centerOfMass [
            0 0 0.035
          ]
        }
        linearVelocity -0.04916249225047512 0.011706028148538342 -0.054285862105865196
        angularVelocity -0.232323532556303 0.2993897210597979 -0.17968173728619663
      }
    }
    HingeJoint {
      jointParameters HingeJointParameters {
        position 0.00010388399893961991
        anchor 0.15 -0.02 -0.12
        minStop -0.8
        maxStop 0.8
        dampingConstant 0.05
      }
      device [
        RotationalMotor {
          name "FR_hip_yaw"
          maxVelocity 5
          maxTorque 5
        }
        PositionSensor {
          name "FR_hip_yaw_sensor"
        }
      ]
      endPoint Solid {
        translation 0.1500127483436573 -0.01998388075619369 -0.12018185915921006
        rotation 1 0 0 0.1310041900993544
        children [
          Shape {
            appearance PBRAppearance {
              baseColor 1 0.2 0
              roughness 1
              metalness 0
            }
            geometry Sphere {
              radius 0.025
            }
          }
          Pose {
            translation 0 0 -0.035
            children [
              Shape {
                appearance PBRAppearance {
                  baseColor 0.7 0.2 0.8
                  roughness 1
                  metalness 0
                }
                geometry Box {
                  size 0.035 0.035 0.07
                }
              }
            ]
          }
          HingeJoint {
            jointParameters HingeJointParameters {
              position 0.8048535633542745
              axis 0 0 1
              anchor 0 0 -0.07
              minStop -1.57
              maxStop 1.57
              dampingConstant 0.05
            }
            device [
              RotationalMotor {
                name "FR_hip_pitch"
                maxVelocity 5
                maxTorque 5
              }
              PositionSensor {
                name "FR_hip_pitch_sensor"
              }
            ]
            endPoint Solid {
              translation 0 0 -0.07
              rotation 0 0 1 0.8048535633542745
              children [
                Shape {
                  appearance PBRAppearance {
                    baseColor 0.1 0.2 1
                    roughness 1
                    metalness 0
                  }
                  geometry Sphere {
                    radius 0.022
                  }
                }
                Pose {
                  translation 0 -0.08 0
                  children [
                    Shape {
                      appearance PBRAppearance {
                        baseColor 0.6 0.1 0.6
                        roughness 1
                        metalness 0
                      }
                      geometry Box {
                        size 0.035 0.16 0.035
                      }
                    }
                  ]
                }
                HingeJoint {
                  jointParameters HingeJointParameters {
                    position -1.6304636416765625
                    axis 0 0 1
                    anchor 0 -0.16 0
                    minStop -2.2
                    maxStop 0.2
                    dampingConstant 0.05
                  }
                  device [
                    RotationalMotor {
                      name "FR_knee_pitch"
                      maxVelocity 5
                      maxTorque 5
                    }
                    PositionSensor {
                      name "FR_knee_pitch_sensor"
                    }
                  ]
                  endPoint Solid {
                    translation 0 -0.16 0
                    rotation 0 0 -1 1.6304636416765625
                    children [
                      Shape {
                        appearance PBRAppearance {
                          baseColor 0.1 0.2 1
                          roughness 1
                          metalness 0
                        }
                        geometry Sphere {
                          radius 0.02
                        }
                      }
                      Pose {
                        translation 0 -0.08 0
                        children [
                          Shape {
                            appearance PBRAppearance {
                              baseColor 0.8 0.7 0.2
                              roughness 1
                              metalness 0
                            }
                            geometry Box {
                              size 0.03 0.16 0.03
                            }
                          }
                        ]
                      }
                      Pose {
                        translation 0 -0.16 0
                        children [
                          Shape {
                            appearance PBRAppearance {
                              baseColor 0 0 0
                              roughness 1
                              metalness 0
                            }
                            geometry Sphere {
                              radius 0.018
                            }
                          }
                        ]
                      }
                    ]
                    name "FR_L3_shank_link"
                    boundingObject Pose {
                      translation 0 -0.08 0
                      children [
                        Box {
                          size 0.03 0.16 0.03
                        }
                      ]
                    }
                    physics Physics {
                      density -1
                      mass 0.08
                      centerOfMass [
                        0 -0.08 0
                      ]
                    }
                    linearVelocity 0.038131061036893864 0.1500484376882702 0.05541228475336889
                    angularVelocity -0.11486564362508656 0.36944811634571506 -0.5228186856266754
                  }
                }
              ]
              name "FR_L2_thigh_link"
              boundingObject Pose {
                translation 0 -0.08 0
                children [
                  Box {
                    size 0.035 0.16 0.035
                  }
                ]
              }
              physics Physics {
                density -1
                mass 0.12
                centerOfMass [
                  0 -0.08 0
                ]
              }
              linearVelocity -0.034099836964118 0.019929169753064385 -0.03205855769517652
              angularVelocity -0.9295206071593538 -0.11392279837875041 1.8358143183107989
            }
          }
        ]
        name "FR_L1_yaw_link"
        boundingObject Pose {
          translation 0 0 -0.035
          children [
            Box {
              size 0.035 0.035 0.07
            }
          ]
        }
        physics Physics {
          density -1
          mass 0.05
          centerOfMass [
            0 0 -0.035
          ]
        }
        locked TRUE
        linearVelocity -0.13355808502918154 -0.07420513463084241 -0.08807187175546374
        angularVelocity -0.2333509288079526 0.29948680955592244 -0.18004724349214193
      }
    }
    HingeJoint {
      jointParameters HingeJointParameters {
        position 0.00039340988406020536
        anchor -0.15 -0.02 0.12
        minStop -0.8
        maxStop 0.8
        dampingConstant 0.05
      }
      device [
        RotationalMotor {
          name "RL_hip_yaw"
          maxVelocity 5
          maxTorque 5
        }
        PositionSensor {
          name "RL_hip_yaw_sensor"
        }
      ]
      endPoint Solid {
        translation -0.14998736704301166 -0.019984366111348593 0.11987702049195367
        rotation -1 0 0 0.13050628401552056
        children [
          Shape {
            appearance PBRAppearance {
              baseColor 1 0.2 0
              roughness 1
              metalness 0
            }
            geometry Sphere {
              radius 0.025
            }
          }
          Pose {
            translation 0 0 0.035
            children [
              Shape {
                appearance PBRAppearance {
                  baseColor 0.7 0.2 0.8
                  roughness 1
                  metalness 0
                }
                geometry Box {
                  size 0.035 0.035 0.07
                }
              }
            ]
          }
          HingeJoint {
            jointParameters HingeJointParameters {
              position 0.803828732268335
              axis 0 0 1
              anchor 0 0 0.07
              minStop -1.57
              maxStop 1.57
              dampingConstant 0.05
            }
            device [
              RotationalMotor {
                name "RL_hip_pitch"
                maxVelocity 5
                maxTorque 5
              }
              PositionSensor {
                name "RL_hip_pitch_sensor"
              }
            ]
            endPoint Solid {
              translation 0 0 0.07
              rotation 0 0 1 0.8038287322683348
              children [
                Shape {
                  appearance PBRAppearance {
                    baseColor 0.1 0.2 1
                    roughness 1
                    metalness 0
                  }
                  geometry Sphere {
                    radius 0.022
                  }
                }
                Pose {
                  translation 0 -0.08 0
                  children [
                    Shape {
                      appearance PBRAppearance {
                        baseColor 0.6 0.1 0.6
                        roughness 1
                        metalness 0
                      }
                      geometry Box {
                        size 0.035 0.16 0.035
                      }
                    }
                  ]
                }
                HingeJoint {
                  jointParameters HingeJointParameters {
                    position -1.6236249252592527
                    axis 0 0 1
                    anchor 0 -0.16 0
                    minStop -2.2
                    maxStop 0.2
                    dampingConstant 0.05
                  }
                  device [
                    RotationalMotor {
                      name "RL_knee_pitch"
                      maxVelocity 5
                      maxTorque 5
                    }
                    PositionSensor {
                      name "RL_knee_pitch_sensor"
                    }
                  ]
                  endPoint Solid {
                    translation 0 -0.16 0
                    rotation 0 0 -1 1.623624925259253
                    children [
                      Shape {
                        appearance PBRAppearance {
                          baseColor 0.1 0.2 1
                          roughness 1
                          metalness 0
                        }
                        geometry Sphere {
                          radius 0.02
                        }
                      }
                      Pose {
                        translation 0 -0.08 0
                        children [
                          Shape {
                            appearance PBRAppearance {
                              baseColor 0.8 0.7 0.2
                              roughness 1
                              metalness 0
                            }
                            geometry Box {
                              size 0.03 0.16 0.03
                            }
                          }
                        ]
                      }
                      Pose {
                        translation 0 -0.16 0
                        children [
                          Shape {
                            appearance PBRAppearance {
                              baseColor 0 0 0
                              roughness 1
                              metalness 0
                            }
                            geometry Sphere {
                              radius 0.018
                            }
                          }
                        ]
                      }
                    ]
                    name "RL_L3_shank_link"
                    boundingObject Pose {
                      translation 0 -0.08 0
                      children [
                        Box {
                          size 0.03 0.16 0.03
                        }
                      ]
                    }
                    physics Physics {
                      density -1
                      mass 0.08
                      centerOfMass [
                        0 -0.08 0
                      ]
                    }
                    linearVelocity 0.05766661582585065 -0.22000630172793226 0.1215603351333421
                    angularVelocity -1.40611327497193 0.564916676818302 3.469255612740253
                  }
                }
              ]
              name "RL_L2_thigh_link"
              boundingObject Pose {
                translation 0 -0.08 0
                children [
                  Box {
                    size 0.035 0.16 0.035
                  }
                ]
              }
              physics Physics {
                density -1
                mass 0.12
                centerOfMass [
                  0 -0.08 0
                ]
              }
              linearVelocity -0.0826597603907537 0.032802982118433216 0.022662267982755946
              angularVelocity -0.15255531534669253 0.2806741254817787 -0.44152493702043016
            }
          }
        ]
        name "RL_L1_yaw_link"
        boundingObject Pose {
          translation 0 0 0.035
          children [
            Box {
              size 0.035 0.035 0.07
            }
          ]
        }
        physics Physics {
          density -1
          mass 0.05
          centerOfMass [
            0 0 0.035
          ]
        }
        linearVelocity -0.07228382514184689 0.04132458651484924 0.02470700355008997
        angularVelocity -0.23614629948150512 0.29974427583861674 -0.180926040204159
      }
    }
    HingeJoint {
      jointParameters HingeJointParameters {
        position -8.12694653696874e-06
        anchor -0.15 -0.02 -0.12
        minStop -0.8
        maxStop 0.8
        dampingConstant 0.05
      }
      device [
        RotationalMotor {
          name "RR_hip_yaw"
          maxVelocity 5
          maxTorque 5
        }
        PositionSensor {
          name "RR_hip_yaw_sensor"
        }
      ]
      endPoint Solid {
        translation -0.1499997403010806 -0.020003630635286263 -0.12018426194099553
        rotation 1 0 0 0.13089156695304235
        children [
          Shape {
            appearance PBRAppearance {
              baseColor 1 0.2 0
              roughness 1
              metalness 0
            }
            geometry Sphere {
              radius 0.025
            }
          }
          Pose {
            translation 0 0 -0.035
            children [
              Shape {
                appearance PBRAppearance {
                  baseColor 0.7 0.2 0.8
                  roughness 1
                  metalness 0
                }
                geometry Box {
                  size 0.035 0.035 0.07
                }
              }
            ]
          }
          HingeJoint {
            jointParameters HingeJointParameters {
              position 0.9062068954264232
              axis 0 0 1
              anchor 0 0 -0.07
              minStop -1.57
              maxStop 1.57
              dampingConstant 0.05
            }
            device [
              RotationalMotor {
                name "RR_hip_pitch"
                maxVelocity 5
                maxTorque 5
              }
              PositionSensor {
                name "RR_hip_pitch_sensor"
              }
            ]
            endPoint Solid {
              translation 0 0 -0.07
              rotation 0 0 0.9999999999999999 0.9062068954264233
              children [
                Shape {
                  appearance PBRAppearance {
                    baseColor 0.1 0.2 1
                    roughness 1
                    metalness 0
                  }
                  geometry Sphere {
                    radius 0.022
                  }
                }
                Pose {
                  translation 0 -0.08 0
                  children [
                    Shape {
                      appearance PBRAppearance {
                        baseColor 0.6 0.1 0.6
                        roughness 1
                        metalness 0
                      }
                      geometry Box {
                        size 0.035 0.16 0.035
                      }
                    }
                  ]
                }
                HingeJoint {
                  jointParameters HingeJointParameters {
                    position -1.8082882230839705
                    axis 0 0 1
                    anchor 0 -0.16 0
                    minStop -2.2
                    maxStop 0.2
                    dampingConstant 0.05
                  }
                  device [
                    RotationalMotor {
                      name "RR_knee_pitch"
                      maxVelocity 5
                      maxTorque 5
                    }
                    PositionSensor {
                      name "RR_knee_pitch_sensor"
                    }
                  ]
                  endPoint Solid {
                    translation 0 -0.16 0
                    rotation 0 0 -1 1.8082882230839705
                    children [
                      Shape {
                        appearance PBRAppearance {
                          baseColor 0.1 0.2 1
                          roughness 1
                          metalness 0
                        }
                        geometry Sphere {
                          radius 0.02
                        }
                      }
                      Pose {
                        translation 0 -0.08 0
                        children [
                          Shape {
                            appearance PBRAppearance {
                              baseColor 0.8 0.7 0.2
                              roughness 1
                              metalness 0
                            }
                            geometry Box {
                              size 0.03 0.16 0.03
                            }
                          }
                        ]
                      }
                      Pose {
                        translation 0 -0.16 0
                        children [
                          Shape {
                            appearance PBRAppearance {
                              baseColor 0 0 0
                              roughness 1
                              metalness 0
                            }
                            geometry Sphere {
                              radius 0.018
                            }
                          }
                        ]
                      }
                    ]
                    name "RR_L3_shank_link"
                    boundingObject Pose {
                      translation 0 -0.08 0
                      children [
                        Box {
                          size 0.03 0.16 0.03
                        }
                      ]
                    }
                    physics Physics {
                      density -1
                      mass 0.08
                      centerOfMass [
                        0 -0.08 0
                      ]
                    }
                    linearVelocity -0.30929790535119744 0.043034617950076265 -0.012966080973281086
                    angularVelocity 0.42298785242115566 0.6882046715635977 -2.077256732365094
                  }
                }
              ]
              name "RR_L2_thigh_link"
              boundingObject Pose {
                translation 0 -0.08 0
                children [
                  Box {
                    size 0.035 0.16 0.035
                  }
                ]
              }
              physics Physics {
                density -1
                mass 0.12
                centerOfMass [
                  0 -0.08 0
                ]
              }
              linearVelocity -0.18216728555688705 -0.07457821667466369 -0.025068627018568032
              angularVelocity -0.16638687890263548 0.3387543095372869 -0.37062933662472464
            }
          }
        ]
        name "RR_L1_yaw_link"
        boundingObject Pose {
          translation 0 0 -0.035
          children [
            Box {
              size 0.035 0.035 0.07
            }
          ]
        }
        physics Physics {
          density -1
          mass 0.05
          centerOfMass [
            0 0 -0.035
          ]
        }
        linearVelocity -0.15680392006245364 -0.04470250654787716 -0.008957875996849614
        angularVelocity -0.23229726544787976 0.2994032647402288 -0.17970853723147462
      }
    }
  ]
  name "quad_3dof_L123"
  boundingObject Box {
    size 0.4 0.08 0.2
  }
  physics Physics {
    density -1
    mass 1
    centerOfMass [
      0 0 0
    ]
  }
  controller "SMC_12DOF"
  linearVelocity -0.09980071154915918 -0.016320232647830894 -0.03537111983033732
  angularVelocity -0.2323848029890334 0.2993914185262172 -0.1797181220892286
}
RectangleArena {
  translation -0.583992 0 -0.43044
  rotation 0.9884496090741877 0.1071619576180971 0.1071619576180971 -1.582415307179586
  floorSize 100 100
}
