#VRML_SIM R2025a utf8

EXTERNPROTO "https://raw.githubusercontent.com/cyberbotics/webots/R2025a/projects/objects/backgrounds/protos/TexturedBackground.proto"
EXTERNPROTO "https://raw.githubusercontent.com/cyberbotics/webots/R2025a/projects/objects/backgrounds/protos/TexturedBackgroundLight.proto"
EXTERNPROTO "https://raw.githubusercontent.com/cyberbotics/webots/R2025a/projects/objects/floors/protos/RectangleArena.proto"

WorldInfo {
  basicTimeStep 1
  coordinateSystem "NUE"
}
Viewpoint {
  orientation 0.32722355449769547 0.5261191402369217 0.7849352811909119 4.162690324512787
  position -0.7127448606980715 1.8314568176736976 -4.618207467514689
}
TexturedBackground {
}
TexturedBackgroundLight {
}
Robot {
  translation -2.5558775668763802 0.25 -0.917193760053533
  rotation 0 1 0 0
  children [
    Shape {
      appearance PBRAppearance {
        baseColor 0 0.9 0.9
        roughness 1
        metalness 0
      }
      geometry Box {
        size 0.4 0.08 0.2
      }
    }
    GPS {
      name "base_gps"
      resolution 0.001
    }
    HingeJoint {
      jointParameters HingeJointParameters {
        position 0
        anchor 0.15 -0.02 0.12
        minStop -0.8
        maxStop 0.8
        dampingConstant 0.35
      }
      device [
        RotationalMotor {
          name "FL_hip_yaw"
          maxVelocity 5
          maxTorque 5
        }
        PositionSensor {
          name "FL_hip_yaw_sensor"
        }
      ]
      endPoint Solid {
        translation 0.15 -0.02 0.12
        rotation 0 1 0 0
        children [
          Shape {
            appearance PBRAppearance {
              baseColor 1 0.2 0
              roughness 1
              metalness 0
            }
            geometry Sphere {
              radius 0.025
            }
          }
          Pose {
            translation 0.0 0.0 -0.035
            children [
              Shape {
                appearance PBRAppearance {
                  baseColor 0.7 0.2 0.8
                  roughness 1
                  metalness 0
                }
                geometry Box {
                  size 0.035 0.035 0.07
                }
              }
            ]
          }
          HingeJoint {
            jointParameters HingeJointParameters {
              position 0.8127555613686607
              axis 0.0 0.0 1.0
              anchor 0.0 0.0 -0.07
              minStop -1.57
              maxStop 1.57
              dampingConstant 0.35
            }
            device [
              RotationalMotor {
                name "FL_hip_pitch"
                maxVelocity 5
                maxTorque 5
              }
              PositionSensor {
                name "FL_hip_pitch_sensor"
              }
            ]
            endPoint Solid {
              translation 0.0 0.0 0.0
              rotation 0.0 0.0 1.0 0.8127555613686607
              children [
                Shape {
                  appearance PBRAppearance {
                    baseColor 0.1 0.2 1
                    roughness 1
                    metalness 0
                  }
                  geometry Sphere {
                    radius 0.022
                  }
                }
                Pose {
                  translation 0.0 -0.08 0.0
                  children [
                    Shape {
                      appearance PBRAppearance {
                        baseColor 0.6 0.1 0.6
                        roughness 1
                        metalness 0
                      }
                      geometry Box {
                        size 0.035 0.16 0.035
                      }
                    }
                  ]
                }
                HingeJoint {
                  jointParameters HingeJointParameters {
                    position -1.6255111227373213
                    axis 0.0 0.0 1.0
                    anchor 0.0 -0.16 0.0
                    minStop -2.2
                    maxStop 0.2
                    dampingConstant 0.35
                  }
                  device [
                    RotationalMotor {
                      name "FL_knee_pitch"
                      maxVelocity 5
                      maxTorque 5
                    }
                    PositionSensor {
                      name "FL_knee_pitch_sensor"
                    }
                  ]
                  endPoint Solid {
                    translation 0.0 -0.16 0.0
                    rotation 0.0 0.0 -1.0 1.6255111227373213
                    children [
                      Shape {
                        appearance PBRAppearance {
                          baseColor 0.1 0.2 1
                          roughness 1
                          metalness 0
                        }
                        geometry Sphere {
                          radius 0.02
                        }
                      }
                      Pose {
                        translation 0.0 -0.08 0.0
                        children [
                          Shape {
                            appearance PBRAppearance {
                              baseColor 0.8 0.7 0.2
                              roughness 1
                              metalness 0
                            }
                            geometry Box {
                              size 0.03 0.16 0.03
                            }
                          }
                        ]
                      }
                      Pose {
                        translation 0.0 -0.16 0.0
                        children [
                          Shape {
                            appearance PBRAppearance {
                              baseColor 0 0 0
                              roughness 1
                              metalness 0
                            }
                            geometry Sphere {
                              radius 0.018
                            }
                          }
                        ]
                      }
                    ]
                    name "FL_L3_shank_link"
                    boundingObject Pose {
                      translation 0.0 -0.08 0.0
                      children [
                        Box {
                          size 0.03 0.16 0.03
                        }
                      ]
                    }
                    physics Physics {
                      density -1
                      mass 0.08
                      centerOfMass [
                        0 -0.08 0
                      ]
                    }
                    linearVelocity 0 0 0
                    angularVelocity 0 0 0
                  }
                }
              ]
              name "FL_L2_thigh_link"
              boundingObject Pose {
                translation 0.0 -0.08 0.0
                children [
                  Box {
                    size 0.035 0.16 0.035
                  }
                ]
              }
              physics Physics {
                density -1
                mass 0.12
                centerOfMass [
                  0 -0.08 0
                ]
              }
              linearVelocity 0 0 0
              angularVelocity 0 0 0
            }
          }
        ]
        name "FL_L1_yaw_link"
        boundingObject Pose {
          translation 0.0 0.0 -0.035
          children [
            Box {
              size 0.035 0.035 0.07
            }
          ]
        }
        physics Physics {
          density -1
          mass 0.05
          centerOfMass [
            0 0 -0.035
          ]
        }
        linearVelocity 0 0 0
        angularVelocity 0 0 0
      }
    }
    HingeJoint {
      jointParameters HingeJointParameters {
        position 0
        anchor 0.15 -0.02 -0.12
        minStop -0.8
        maxStop 0.8
        dampingConstant 0.35
      }
      device [
        RotationalMotor {
          name "FR_hip_yaw"
          maxVelocity 5
          maxTorque 5
        }
        PositionSensor {
          name "FR_hip_yaw_sensor"
        }
      ]
      endPoint Solid {
        translation 0.15 -0.02 -0.12
        rotation 0 1 0 0
        children [
          Shape {
            appearance PBRAppearance {
              baseColor 1 0.2 0
              roughness 1
              metalness 0
            }
            geometry Sphere {
              radius 0.025
            }
          }
          Pose {
            translation 0.0 0.0 0.035
            children [
              Shape {
                appearance PBRAppearance {
                  baseColor 0.7 0.2 0.8
                  roughness 1
                  metalness 0
                }
                geometry Box {
                  size 0.035 0.035 0.07
                }
              }
            ]
          }
          HingeJoint {
            jointParameters HingeJointParameters {
              position 0.8127555613686607
              axis 0.0 0.0 1.0
              anchor 0.0 0.0 0.07
              minStop -1.57
              maxStop 1.57
              dampingConstant 0.35
            }
            device [
              RotationalMotor {
                name "FR_hip_pitch"
                maxVelocity 5
                maxTorque 5
              }
              PositionSensor {
                name "FR_hip_pitch_sensor"
              }
            ]
            endPoint Solid {
              translation 0.0 0.0 0.0
              rotation 0.0 0.0 1.0 0.8127555613686607
              children [
                Shape {
                  appearance PBRAppearance {
                    baseColor 0.1 0.2 1
                    roughness 1
                    metalness 0
                  }
                  geometry Sphere {
                    radius 0.022
                  }
                }
                Pose {
                  translation 0.0 -0.08 0.0
                  children [
                    Shape {
                      appearance PBRAppearance {
                        baseColor 0.6 0.1 0.6
                        roughness 1
                        metalness 0
                      }
                      geometry Box {
                        size 0.035 0.16 0.035
                      }
                    }
                  ]
                }
                HingeJoint {
                  jointParameters HingeJointParameters {
                    position -1.6255111227373213
                    axis 0.0 0.0 1.0
                    anchor 0.0 -0.16 0.0
                    minStop -2.2
                    maxStop 0.2
                    dampingConstant 0.35
                  }
                  device [
                    RotationalMotor {
                      name "FR_knee_pitch"
                      maxVelocity 5
                      maxTorque 5
                    }
                    PositionSensor {
                      name "FR_knee_pitch_sensor"
                    }
                  ]
                  endPoint Solid {
                    translation 0.0 -0.16 0.0
                    rotation 0.0 0.0 -1.0 1.6255111227373213
                    children [
                      Shape {
                        appearance PBRAppearance {
                          baseColor 0.1 0.2 1
                          roughness 1
                          metalness 0
                        }
                        geometry Sphere {
                          radius 0.02
                        }
                      }
                      Pose {
                        translation 0.0 -0.08 0.0
                        children [
                          Shape {
                            appearance PBRAppearance {
                              baseColor 0.8 0.7 0.2
                              roughness 1
                              metalness 0
                            }
                            geometry Box {
                              size 0.03 0.16 0.03
                            }
                          }
                        ]
                      }
                      Pose {
                        translation 0.0 -0.16 0.0
                        children [
                          Shape {
                            appearance PBRAppearance {
                              baseColor 0 0 0
                              roughness 1
                              metalness 0
                            }
                            geometry Sphere {
                              radius 0.018
                            }
                          }
                        ]
                      }
                    ]
                    name "FR_L3_shank_link"
                    boundingObject Pose {
                      translation 0.0 -0.08 0.0
                      children [
                        Box {
                          size 0.03 0.16 0.03
                        }
                      ]
                    }
                    physics Physics {
                      density -1
                      mass 0.08
                      centerOfMass [
                        0 -0.08 0
                      ]
                    }
                    linearVelocity 0 0 0
                    angularVelocity 0 0 0
                  }
                }
              ]
              name "FR_L2_thigh_link"
              boundingObject Pose {
                translation 0.0 -0.08 0.0
                children [
                  Box {
                    size 0.035 0.16 0.035
                  }
                ]
              }
              physics Physics {
                density -1
                mass 0.12
                centerOfMass [
                  0 -0.08 0
                ]
              }
              linearVelocity 0 0 0
              angularVelocity 0 0 0
            }
          }
        ]
        name "FR_L1_yaw_link"
        boundingObject Pose {
          translation 0.0 0.0 0.035
          children [
            Box {
              size 0.035 0.035 0.07
            }
          ]
        }
        physics Physics {
          density -1
          mass 0.05
          centerOfMass [
            0 0 0.035
          ]
        }
        linearVelocity 0 0 0
        angularVelocity 0 0 0
      }
    }
    HingeJoint {
      jointParameters HingeJointParameters {
        position 0
        anchor -0.15 -0.02 0.12
        minStop -0.8
        maxStop 0.8
        dampingConstant 0.35
      }
      device [
        RotationalMotor {
          name "RL_hip_yaw"
          maxVelocity 5
          maxTorque 5
        }
        PositionSensor {
          name "RL_hip_yaw_sensor"
        }
      ]
      endPoint Solid {
        translation -0.15 -0.02 0.12
        rotation 0 1 0 0
        children [
          Shape {
            appearance PBRAppearance {
              baseColor 1 0.2 0
              roughness 1
              metalness 0
            }
            geometry Sphere {
              radius 0.025
            }
          }
          Pose {
            translation 0.0 0.0 -0.035
            children [
              Shape {
                appearance PBRAppearance {
                  baseColor 0.7 0.2 0.8
                  roughness 1
                  metalness 0
                }
                geometry Box {
                  size 0.035 0.035 0.07
                }
              }
            ]
          }
          HingeJoint {
            jointParameters HingeJointParameters {
              position 0.8127555613686607
              axis 0.0 0.0 1.0
              anchor 0.0 0.0 -0.07
              minStop -1.57
              maxStop 1.57
              dampingConstant 0.35
            }
            device [
              RotationalMotor {
                name "RL_hip_pitch"
                maxVelocity 5
                maxTorque 5
              }
              PositionSensor {
                name "RL_hip_pitch_sensor"
              }
            ]
            endPoint Solid {
              translation 0.0 0.0 0.0
              rotation 0.0 0.0 1.0 0.8127555613686607
              children [
                Shape {
                  appearance PBRAppearance {
                    baseColor 0.1 0.2 1
                    roughness 1
                    metalness 0
                  }
                  geometry Sphere {
                    radius 0.022
                  }
                }
                Pose {
                  translation 0.0 -0.08 0.0
                  children [
                    Shape {
                      appearance PBRAppearance {
                        baseColor 0.6 0.1 0.6
                        roughness 1
                        metalness 0
                      }
                      geometry Box {
                        size 0.035 0.16 0.035
                      }
                    }
                  ]
                }
                HingeJoint {
                  jointParameters HingeJointParameters {
                    position -1.6255111227373213
                    axis 0.0 0.0 1.0
                    anchor 0.0 -0.16 0.0
                    minStop -2.2
                    maxStop 0.2
                    dampingConstant 0.35
                  }
                  device [
                    RotationalMotor {
                      name "RL_knee_pitch"
                      maxVelocity 5
                      maxTorque 5
                    }
                    PositionSensor {
                      name "RL_knee_pitch_sensor"
                    }
                  ]
                  endPoint Solid {
                    translation 0.0 -0.16 0.0
                    rotation 0.0 0.0 -1.0 1.6255111227373213
                    children [
                      Shape {
                        appearance PBRAppearance {
                          baseColor 0.1 0.2 1
                          roughness 1
                          metalness 0
                        }
                        geometry Sphere {
                          radius 0.02
                        }
                      }
                      Pose {
                        translation 0.0 -0.08 0.0
                        children [
                          Shape {
                            appearance PBRAppearance {
                              baseColor 0.8 0.7 0.2
                              roughness 1
                              metalness 0
                            }
                            geometry Box {
                              size 0.03 0.16 0.03
                            }
                          }
                        ]
                      }
                      Pose {
                        translation 0.0 -0.16 0.0
                        children [
                          Shape {
                            appearance PBRAppearance {
                              baseColor 0 0 0
                              roughness 1
                              metalness 0
                            }
                            geometry Sphere {
                              radius 0.018
                            }
                          }
                        ]
                      }
                    ]
                    name "RL_L3_shank_link"
                    boundingObject Pose {
                      translation 0.0 -0.08 0.0
                      children [
                        Box {
                          size 0.03 0.16 0.03
                        }
                      ]
                    }
                    physics Physics {
                      density -1
                      mass 0.08
                      centerOfMass [
                        0 -0.08 0
                      ]
                    }
                    linearVelocity 0 0 0
                    angularVelocity 0 0 0
                  }
                }
              ]
              name "RL_L2_thigh_link"
              boundingObject Pose {
                translation 0.0 -0.08 0.0
                children [
                  Box {
                    size 0.035 0.16 0.035
                  }
                ]
              }
              physics Physics {
                density -1
                mass 0.12
                centerOfMass [
                  0 -0.08 0
                ]
              }
              linearVelocity 0 0 0
              angularVelocity 0 0 0
            }
          }
        ]
        name "RL_L1_yaw_link"
        boundingObject Pose {
          translation 0.0 0.0 -0.035
          children [
            Box {
              size 0.035 0.035 0.07
            }
          ]
        }
        physics Physics {
          density -1
          mass 0.05
          centerOfMass [
            0 0 -0.035
          ]
        }
        linearVelocity 0 0 0
        angularVelocity 0 0 0
      }
    }
    HingeJoint {
      jointParameters HingeJointParameters {
        position 0
        anchor -0.15 -0.02 -0.12
        minStop -0.8
        maxStop 0.8
        dampingConstant 0.35
      }
      device [
        RotationalMotor {
          name "RR_hip_yaw"
          maxVelocity 5
          maxTorque 5
        }
        PositionSensor {
          name "RR_hip_yaw_sensor"
        }
      ]
      endPoint Solid {
        translation -0.15 -0.02 -0.12
        rotation 0 1 0 0
        children [
          Shape {
            appearance PBRAppearance {
              baseColor 1 0.2 0
              roughness 1
              metalness 0
            }
            geometry Sphere {
              radius 0.025
            }
          }
          Pose {
            translation 0.0 0.0 0.035
            children [
              Shape {
                appearance PBRAppearance {
                  baseColor 0.7 0.2 0.8
                  roughness 1
                  metalness 0
                }
                geometry Box {
                  size 0.035 0.035 0.07
                }
              }
            ]
          }
          HingeJoint {
            jointParameters HingeJointParameters {
              position 0.8127555613686607
              axis 0.0 0.0 1.0
              anchor 0.0 0.0 0.07
              minStop -1.57
              maxStop 1.57
              dampingConstant 0.35
            }
            device [
              RotationalMotor {
                name "RR_hip_pitch"
                maxVelocity 5
                maxTorque 5
              }
              PositionSensor {
                name "RR_hip_pitch_sensor"
              }
            ]
            endPoint Solid {
              translation 0.0 0.0 0.0
              rotation 0.0 0.0 1.0 0.8127555613686607
              children [
                Shape {
                  appearance PBRAppearance {
                    baseColor 0.1 0.2 1
                    roughness 1
                    metalness 0
                  }
                  geometry Sphere {
                    radius 0.022
                  }
                }
                Pose {
                  translation 0.0 -0.08 0.0
                  children [
                    Shape {
                      appearance PBRAppearance {
                        baseColor 0.6 0.1 0.6
                        roughness 1
                        metalness 0
                      }
                      geometry Box {
                        size 0.035 0.16 0.035
                      }
                    }
                  ]
                }
                HingeJoint {
                  jointParameters HingeJointParameters {
                    position -1.6255111227373213
                    axis 0.0 0.0 1.0
                    anchor 0.0 -0.16 0.0
                    minStop -2.2
                    maxStop 0.2
                    dampingConstant 0.35
                  }
                  device [
                    RotationalMotor {
                      name "RR_knee_pitch"
                      maxVelocity 5
                      maxTorque 5
                    }
                    PositionSensor {
                      name "RR_knee_pitch_sensor"
                    }
                  ]
                  endPoint Solid {
                    translation 0.0 -0.16 0.0
                    rotation 0.0 0.0 -1.0 1.6255111227373213
                    children [
                      Shape {
                        appearance PBRAppearance {
                          baseColor 0.1 0.2 1
                          roughness 1
                          metalness 0
                        }
                        geometry Sphere {
                          radius 0.02
                        }
                      }
                      Pose {
                        translation 0.0 -0.08 0.0
                        children [
                          Shape {
                            appearance PBRAppearance {
                              baseColor 0.8 0.7 0.2
                              roughness 1
                              metalness 0
                            }
                            geometry Box {
                              size 0.03 0.16 0.03
                            }
                          }
                        ]
                      }
                      Pose {
                        translation 0.0 -0.16 0.0
                        children [
                          Shape {
                            appearance PBRAppearance {
                              baseColor 0 0 0
                              roughness 1
                              metalness 0
                            }
                            geometry Sphere {
                              radius 0.018
                            }
                          }
                        ]
                      }
                    ]
                    name "RR_L3_shank_link"
                    boundingObject Pose {
                      translation 0.0 -0.08 0.0
                      children [
                        Box {
                          size 0.03 0.16 0.03
                        }
                      ]
                    }
                    physics Physics {
                      density -1
                      mass 0.08
                      centerOfMass [
                        0 -0.08 0
                      ]
                    }
                    linearVelocity 0 0 0
                    angularVelocity 0 0 0
                  }
                }
              ]
              name "RR_L2_thigh_link"
              boundingObject Pose {
                translation 0.0 -0.08 0.0
                children [
                  Box {
                    size 0.035 0.16 0.035
                  }
                ]
              }
              physics Physics {
                density -1
                mass 0.12
                centerOfMass [
                  0 -0.08 0
                ]
              }
              linearVelocity 0 0 0
              angularVelocity 0 0 0
            }
          }
        ]
        name "RR_L1_yaw_link"
        boundingObject Pose {
          translation 0.0 0.0 0.035
          children [
            Box {
              size 0.035 0.035 0.07
            }
          ]
        }
        physics Physics {
          density -1
          mass 0.05
          centerOfMass [
            0 0 0.035
          ]
        }
        linearVelocity 0 0 0
        angularVelocity 0 0 0
      }
    }
  ]
  name "quad_3dof_L123"
  boundingObject Box {
    size 0.4 0.08 0.2
  }
  physics Physics {
    density -1
    mass 1
    centerOfMass [
      0 0 0
    ]
  }
  controller "<extern>"
  linearVelocity 0 0 0
  angularVelocity 0 0 0
}
RectangleArena {
  translation -0.583992 0 -0.43044
  rotation 0.9884496090741877 0.1071619576180971 0.1071619576180971 -1.582415307179586
  floorSize 100 100
}

